<?xml version="1.0"?>
<robot name="agilex_mini"
    xmlns:xacro="http://www.ros.org/wiki/xacro">

    <xacro:property name="length_wheel" value="0.02" />
    <xacro:property name="radius_wheel" value="0.025" />
    <xacro:macro name="default_inertial" params="mass">
        <inertial>
            <mass value="${mass}" />
            <inertia ixx="1.0" ixy="0.0" ixz="0.0" iyy="1.0" iyz="0.0" izz="1.0" />
        </inertial>
    </xacro:macro>

    <link name="base_footprint">
        <visual>
            <geometry>
                <box size="0.001 0.001 0.001"/>
            </geometry>
            <origin rpy="0 0 0" xyz="0 0 0"/>
        </visual>
        <xacro:default_inertial mass="0.0001"/>
    </link>

    <gazebo reference="base_footprint">
        <material>Gazebo/Green</material>
        <turnGravityOff>false</turnGravityOff>
    </gazebo>

    <joint name="base_footprint_joint" type="fixed">
        <origin xyz="0 0 0" />
        <parent link="base_footprint" />
        <child link="base_link" />
    </joint>

    <link name="base_link">
        <visual>
            <geometry>
                <box size="0.16 0.25 0.05"/>
            </geometry>

            <origin rpy="0 0 1.57075" xyz="0 0 0"/>

            <material name="blue">
                <color rgba="0 .5 .8 1"/>
            </material>
        </visual>

        <collision>
            <geometry>
                <box size="0.25 .16 .05"/>
            </geometry>
        </collision>
        <xacro:default_inertial mass="10"/>
    </link>

    <link name="right_front_wheel">
        <visual>
            <geometry>
                <cylinder length="${length_wheel}" radius="${radius_wheel}"/>
            </geometry>

            <origin rpy="0 0 0" xyz="0 0 0"/>

            <material name="black">
                <color rgba="0 0 0 1"/>
            </material>
        </visual>

        <collision>
            <geometry>
                <cylinder length="${length_wheel}" radius="${radius_wheel}"/>
            </geometry>
        </collision>
        <xacro:default_inertial mass="1"/>
    </link>

    <link name="left_front_wheel">
        <visual>
            <geometry>
                <cylinder length="${length_wheel}" radius="${radius_wheel}"/>
            </geometry>

            <origin rpy="0 0 0" xyz="0 0 0"/>

            <material name="black">
                <color rgba="0 0 0 1"/>
            </material>
        </visual>

        <collision>
            <geometry>
                <cylinder length="${length_wheel}" radius="${radius_wheel}"/>
            </geometry>
        </collision>
        <xacro:default_inertial mass="1"/>
    </link>



    <link name="right_back_wheel">
        <visual>
            <geometry>
                <cylinder length="${length_wheel}" radius="${radius_wheel}"/>
            </geometry>

            <origin rpy="0 0 0" xyz="0 0 0"/>

            <material name="black">
                <color rgba="0 0 0 1"/>
            </material>
        </visual>

        <collision>
            <geometry>
                <cylinder length="${length_wheel}" radius="${radius_wheel}"/>
            </geometry>
        </collision>
        <xacro:default_inertial mass="1"/>
    </link>



    <link name="left_back_wheel">
        <visual>
            <geometry>
                <cylinder length="${length_wheel}" radius="${radius_wheel}"/>
            </geometry>

            <origin rpy="0 0 0" xyz="0 0 0"/>

            <material name="black">
                <color rgba="0 0 0 1"/>
            </material>
        </visual>

        <collision>
            <geometry>
                <cylinder length="${length_wheel}" radius="${radius_wheel}"/>
            </geometry>
        </collision>
        <xacro:default_inertial mass="1"/>
    </link>


    <joint name="right_front_wheel_joint" type="continuous">
        <axis xyz="0 0 1"/>
        <parent link="base_link"/>
        <child link="right_front_wheel"/>
        <origin rpy="-1.57075 0 0" xyz="0.08 0.1 -0.03"/>
    </joint>


    <joint name="left_back_wheel_joint" type="continuous">
        <axis xyz="0 0 1"/>
        <parent link="base_link"/>
        <child link="left_back_wheel"/>
        <origin rpy="-1.57075 0 0" xyz="-0.08 -0.1 -0.03"/>
    </joint>

    <joint name="right_back_wheel_joint" type="continuous">
        <axis xyz="0 0 1"/>
        <parent link="base_link"/>
        <child link="right_back_wheel"/>
        <origin rpy="-1.57075 0 0" xyz="0.08 -0.1 -0.03"/>
    </joint>


    <joint name="left_front_wheel_joint" type="continuous">
        <axis xyz="0 0 1"/>
        <parent link="base_link"/>
        <child link="left_front_wheel"/>
        <origin rpy="-1.57075 0 0" xyz="-0.08 0.1 -0.03"/>
    </joint>

    <!-- controller -->
    <gazebo>
        <plugin name="differential_drive_controller" filename="libgazebo_ros_skid_steer_drive.so">

            <alwaysOn>true</alwaysOn>
            <updateRate>100.0</updateRate>
            <robotNamespace>/</robotNamespace>

            <leftFrontJoint>left_front_wheel_joint</leftFrontJoint>
            <leftRearJoint>left_back_wheel_joint</leftRearJoint>
            <rightFrontJoint>right_front_wheel_joint</rightFrontJoint>
            <rightRearJoint>right_back_wheel_joint</rightRearJoint>

            <wheelSeparation>0.54</wheelSeparation>
            <wheelDiameter>0.14</wheelDiameter>
            <torque>2</torque>
            <commandTopic>cmd_vel</commandTopic>
            <odometryTopic>odom</odometryTopic>
            <odometryFrame>odom</odometryFrame>
            <robotBaseFrame>base_footprint</robotBaseFrame>
            <broadcastTF>1</broadcastTF>
        </plugin>
    </gazebo>


</robot>